<?xml version="1.0"?>
<sdf version="1.7">
  <model name="gazebo_traffic_light">
    <static>false</static>
    
    <link name="light_fixture">
      <gravity>false</gravity>
      <pose>0 0 0 0 0 0</pose>
      <visual name="visual">
        <pose>0 0 0.535 0 0 0</pose>
        <geometry>
          <box>
            <size>0.1 0.6 1.2</size>
          </box>
        </geometry>
        <material>
          <ambient>0 0 0 1</ambient>
          <diffuse>0 0 0 1</diffuse>
          <specular>0 0 0 1</specular>
        </material>
      </visual>
      <collision name="collision">
        <pose>0 0 0.535 0 0 0</pose>
        <geometry>
          <box>
            <size>0.1 0.6 1.2</size>
          </box>
        </geometry>
      </collision>
    </link>
    
    <link name="green_off">
      <gravity>false</gravity>
      <pose>0.075 0 0.175 0 1.5707 0</pose>
      <collision name="collision">
        <geometry>
          <cylinder>
            <radius>0.15</radius>
            <length>0.05</length>
          </cylinder>
        </geometry>
      </collision>

      <visual name="visual">
        <geometry>
          <cylinder>
            <radius>0.15</radius>
            <length>0.05</length>
          </cylinder>
        </geometry>
        <material>
          <ambient>0 1 0 1</ambient>
          <diffuse>0 0 0 1</diffuse>
          <specular>0 0 0 1</specular>
          <emissive>0 0 0 1</emissive>
        </material>
      </visual>
    </link>
    
    <link name="green_on">
      <gravity>false</gravity>
      <pose>0 0 0.175 0 1.5707 0</pose>
      <collision name="collision">
        <geometry>
          <cylinder>
            <radius>0.15</radius>
            <length>0.002</length>
          </cylinder>
        </geometry>
      </collision>

      <visual name="visual">
        <geometry>
          <cylinder>
            <radius>0.15</radius>
            <length>0.002</length>
          </cylinder>
        </geometry>
        <material>
          <ambient>0 0 0 1</ambient>
          <diffuse>0 0 0 1</diffuse>
          <specular>0 0 0 1</specular>
          <emissive>0 1 0 1</emissive>
        </material>
      </visual>
    </link>

    <link name="yellow_off">
      <gravity>false</gravity>
      <pose>0.075 0 0.525 0 1.5707 0</pose>
      <collision name="collision">
        <geometry>
          <cylinder>
            <radius>0.15</radius>
            <length>0.05</length>
          </cylinder>
        </geometry>
      </collision>

      <visual name="visual">
        <geometry>
          <cylinder>
            <radius>0.15</radius>
            <length>0.05</length>
          </cylinder>
        </geometry>
        <material>
          <ambient>1 1 0 1</ambient>
          <diffuse>0 0 0 1</diffuse>
          <specular>0 0 0 1</specular>
          <emissive>0 0 0 1</emissive>
        </material>
      </visual>
    </link>
    
    <link name="yellow_on">
      <gravity>false</gravity>
      <pose>0 0 0.525 0 1.5707 0</pose>
      <collision name="collision">
        <geometry>
          <cylinder>
            <radius>0.15</radius>
            <length>0.002</length>
          </cylinder>
        </geometry>
      </collision>

      <visual name="visual">
        <geometry>
          <cylinder>
            <radius>0.15</radius>
            <length>0.002</length>
          </cylinder>
        </geometry>
        <material>
          <ambient>0 0 0 1</ambient>
          <diffuse>0 0 0 1</diffuse>
          <specular>0 0 0 1</specular>
          <emissive>1 1 0 1</emissive>
        </material>
      </visual>
    </link>
    
    <link name="red_off">
      <gravity>false</gravity>
      <pose>0.075 0 0.875 0 1.5707 0</pose>
      <collision name="collision">
        <geometry>
          <cylinder>
            <radius>0.15</radius>
            <length>0.05</length>
          </cylinder>
        </geometry>
      </collision>

      <visual name="visual">
        <geometry>
          <cylinder>
            <radius>0.15</radius>
            <length>0.05</length>
          </cylinder>
        </geometry>
        <material>
          <ambient>1 0 0 1</ambient>
          <diffuse>0 0 0 1</diffuse>
          <specular>0 0 0 1</specular>
          <emissive>0 0 0 1</emissive>
        </material>
      </visual>
    </link>
    
    <link name="red_on">
      <gravity>false</gravity>
      <pose>0 0 0.875 0 1.5707 0</pose>
      <collision name="collision">
        <geometry>
          <cylinder>
            <radius>0.15</radius>
            <length>0.002</length>
          </cylinder>
        </geometry>
      </collision>

      <visual name="visual">
        <geometry>
          <cylinder>
            <radius>0.15</radius>
            <length>0.002</length>
          </cylinder>
        </geometry>
        <material>
          <ambient>0 0 0 1</ambient>
          <diffuse>0 0 0 1</diffuse>
          <specular>0 0 0 1</specular>
          <emissive>1 0 0 1</emissive>
        </material>
      </visual>
    </link>

    <joint name="green_switch" type="prismatic" >
      <parent>green_off</parent>
      <child>green_on</child>
      <axis>
        <xyz>0 0 1</xyz>
        <limit>
          <lower>0</lower>
          <upper>0.101</upper>
        </limit>
      </axis>
    </joint>

    <joint name="green_base" type="fixed" >
      <parent>light_fixture</parent>
      <child>green_off</child>
    </joint>

    <joint name="yellow_switch" type="prismatic" >
      <parent>yellow_off</parent>
      <child>yellow_on</child>
      <axis>
        <xyz>0 0 1</xyz>
        <limit>
          <lower>0</lower>
          <upper>0.101</upper>
        </limit>
      </axis>
    </joint>

    <joint name="yellow_base" type="fixed" >
      <parent>light_fixture</parent>
      <child>yellow_off</child>
    </joint>

    <joint name="red_switch" type="prismatic" >
      <parent>red_off</parent>
      <child>red_on</child>
      <axis>
        <xyz>0 0 1</xyz>
        <limit>
          <lower>0</lower>
          <upper>0.101</upper>
        </limit>
      </axis>
    </joint>

    <joint name="red_base" type="fixed" >
      <parent>light_fixture</parent>
      <child>red_off</child>
    </joint>
  </model>
</sdf>
